{
  "schema_version": "1.4.0",
  "id": "GHSA-rwqr-c348-m5wr",
  "modified": "2022-07-05T21:27:19Z",
  "published": "2022-06-24T00:00:31Z",
  "withdrawn": "2022-06-28T16:39:06Z",
  "aliases": [
    "CVE-2022-33124"
  ],
  "summary": "Withdrawn: Denial of Service in aiohttp",
  "details": "## Withdrawn\nThis advisory has been withdrawn because the maintainers of aiohttp and multiple third parties disputed the validity of the issue. There is not sufficient evidence for the claims in the original report.\n\n## Original Description\naiohttp v3.8.1 was discovered to contain an invalid IPv6 URL which can lead to a Denial of Service (DoS).",
  "severity": [
    {
      "type": "CVSS_V3",
      "score": "CVSS:3.1/AV:L/AC:L/PR:N/UI:R/S:U/C:N/I:N/A:H"
    }
  ],
  "affected": [
    {
      "package": {
        "ecosystem": "PyPI",
        "name": "aiohttp"
      },
      "ranges": [
        {
          "type": "ECOSYSTEM",
          "events": [
            {
              "introduced": "0"
            },
            {
              "last_affected": "3.8.1"
            }
          ]
        }
      ]
    }
  ],
  "references": [
    {
      "type": "ADVISORY",
      "url": "https://nvd.nist.gov/vuln/detail/CVE-2022-33124"
    },
    {
      "type": "WEB",
      "url": "https://github.com/aio-libs/aiohttp/issues/6772"
    },
    {
      "type": "PACKAGE",
      "url": "https://github.com/aio-libs/aiohttp"
    }
  ],
  "database_specific": {
    "cwe_ids": [

    ],
    "severity": "MODERATE",
    "github_reviewed": true,
    "github_reviewed_at": "2022-06-25T07:22:37Z",
    "nvd_published_at": "2022-06-23T17:15:00Z"
  }
}